import type { PromiseResult } from '@jonasb/datadata-core';
import { ErrorType, notOk, ok } from '@jonasb/datadata-core';
import type { AuthContext, AuthCreateSessionPayload, DatabaseAdapter, TransactionContext } from '.';
import { ensureRequired } from './Assertions';
import * as Db from './Database';
import type { SubjectsTable } from './DatabaseTables';

export interface Session {
  readonly subjectInternalId: number;
  /** UUID */
  readonly subjectId: string;
}

export async function authCreateSession(
  databaseAdapter: DatabaseAdapter,
  context: TransactionContext,
  provider: string,
  identifier: string
): PromiseResult<AuthCreateSessionPayload, ErrorType.BadRequest | ErrorType.Generic> {
  const assertion = ensureRequired({ provider, identifier });
  if (assertion.isError()) {
    return assertion;
  }

  return await databaseAdapter.authCreateSession(context, provider, identifier);
}

export async function createSessionForPrincipal(
  context: AuthContext,
  provider: string,
  identifier: string,
  options?: {
    createPrincipalIfMissing?: boolean;
  }
): PromiseResult<Session, ErrorType.BadRequest | ErrorType.NotFound> {
  const assertion = ensureRequired({ provider, identifier });
  if (assertion.isError()) {
    return assertion;
  }
  try {
    const { id, uuid } = await Db.queryOne<Pick<SubjectsTable, 'id' | 'uuid'>>(
      context,
      'SELECT s.id, s.uuid FROM subjects s, principals p WHERE p.provider = $1 AND p.identifier = $2 AND p.subjects_id = s.id',
      [provider, identifier]
    );
    return ok({ subjectInternalId: id, subjectId: uuid });
  } catch (error) {
    if (error instanceof Db.UnexpectedQuantityError) {
      if (options?.createPrincipalIfMissing) {
        const creationResult = await doCreatePrincipal(context, provider, identifier);
        if (creationResult.isOk()) {
          return creationResult.map((it) => it);
        }
        if (creationResult.isErrorType(ErrorType.Conflict)) {
          // this should only happen if the principal is created by another request after our first check
          return await createSessionForPrincipal(context, provider, identifier);
        }
        // TODO Not sure how we could end up here. Ok to fall back to not found error?
      }
      return notOk.NotFound('Principal doesnâ€™t exist');
    }
    throw error;
  }
}

/**
 *
 * @param context
 * @param provider
 * @param identifier
 * @returns The uuid of the created principal
 */
export async function createPrincipal(
  context: AuthContext,
  provider: string,
  identifier: string
): PromiseResult<string, ErrorType.BadRequest | ErrorType.Conflict | ErrorType.Generic> {
  const result = await doCreatePrincipal(context, provider, identifier);
  return result.isOk() ? result.map(({ subjectId }) => subjectId) : result;
}

async function doCreatePrincipal(
  context: AuthContext,
  provider: string,
  identifier: string
): PromiseResult<Session, ErrorType.BadRequest | ErrorType.Conflict | ErrorType.Generic> {
  const assertion = ensureRequired({ provider, identifier });
  if (assertion.isError()) {
    return assertion;
  }
  return await context.databaseAdapter.authCreatePrincipal(context, provider, identifier);
}
